Workbook

Sheet ChiTieu
A1: Ngày | B1: Nhóm | C1: Đối tượng | D1: Khoản chi | E1: Số tiền | F1: Thanh toán | G1: Ghi chú | H1: Tag | I1: Tiền tháng chọn | J1: Hạng tiền
A2: 46226 | B2: Ăn sáng | C2: Bản thân | D2: Mì Quảng | E2: 30000 | F2: Momo | G2: Bà Ngọc | H2: Bản thân | I2: =IF(AND(A2>=Dashboard!$B$2,A2<EDATE(Dashboard!$B$2,1),D2<>""),E2,"") -> 30000 | J2: =IF(I2="","",RANK(I2,$I$2:$I$1014,0)+COUNTIF($I$2:I2,I2)-1) -> #REF!
A3: 46226 | B3: Cafe | C3: Bản thân | D3: Cà phê sữa | E3: 29000 | F3: Thẻ SHB | G3: Hightlands | H3: Bản thân | I3: =IF(AND(A3>=Dashboard!$B$2,A3<EDATE(Dashboard!$B$2,1),D3<>""),E3,"") -> 29000 | J3: =IF(I3="","",RANK(I3,$I$2:$I$1014,0)+COUNTIF($I$2:I3,I3)-1) -> #REF!
A4: 46226 | B4: Ăn tối | C4: Bản thân | D4: Cơm | E4: 27000 | F4: VCB | G4: An Nhiên | H4: Bản thân | I4: =IF(AND(A4>=Dashboard!$B$2,A4<EDATE(Dashboard!$B$2,1),D4<>""),E4,"") -> 27000 | J4: =IF(I4="","",RANK(I4,$I$2:$I$1014,0)+COUNTIF($I$2:I4,I4)-1) -> #REF!
A5: 46226 | B5: May mắn | C5: Bản thân | D5: Vietlott | E5: 10000 | F5: App Vietlot | G5: Vietlott | H5: Bản thân | I5: =IF(AND(A5>=Dashboard!$B$2,A5<EDATE(Dashboard!$B$2,1),D5<>""),E5,"") -> 10000 | J5: =IF(I5="","",RANK(I5,$I$2:$I$1014,0)+COUNTIF($I$2:I5,I5)-1) -> #REF!
A6: 46226 | B6: May mắn | C6: Bản thân | D6: Vé số | E6: 20000 | F6: Tiền mặt | G6: Vé số | H6: Bản thân | I6: =IF(AND(A6>=Dashboard!$B$2,A6<EDATE(Dashboard!$B$2,1),D6<>""),E6,"") -> 20000 | J6: =IF(I6="","",RANK(I6,$I$2:$I$1014,0)+COUNTIF($I$2:I6,I6)-1) -> #REF!
A7: 46227 | B7: Cafe | C7: Bản thân | D7: Cà phê sữa | E7: 26000 | F7: Momo | G7: Ông Bầu | H7: Bản thân | I7: =IF(AND(A56>=Dashboard!$B$2,A56<EDATE(Dashboard!$B$2,1),D56<>""),E56,"") -> 50000 | J7: =IF(I7="","",RANK(I7,$I$2:$I$1014,0)+COUNTIF($I$2:I7,I7)-1) -> #REF!
A8: 46227 | B8: Ăn trưa | C8: Bản thân | D8: Cơm | E8: 27000 | F8: VCB | G8: An Nhiên | H8: Bản thân | I8: =IF(AND(A57>=Dashboard!$B$2,A57<EDATE(Dashboard!$B$2,1),D57<>""),E57,"") -> 60000 | J8: =IF(I8="","",RANK(I8,$I$2:$I$1014,0)+COUNTIF($I$2:I8,I8)-1) -> #REF!
A9: 46227 | B9: May mắn | C9: Bản thân | D9: Vietlott | E9: 10000 | F9: App Vietlot | G9: Vietlott | H9: Bản thân | I9: =IF(AND(A58>=Dashboard!$B$2,A58<EDATE(Dashboard!$B$2,1),D58<>""),E58,"") -> 30000 | J9: =IF(I9="","",RANK(I9,$I$2:$I$1014,0)+COUNTIF($I$2:I9,I9)-1) -> #REF!
A10: 46227 | B10: May mắn | C10: Bản thân | D10: Vé số | E10: 30000 | F10: Tiền mặt | G10: Vé số | H10: Bản thân | I10: =IF(AND(A10>=Dashboard!$B$2,A10<EDATE(Dashboard!$B$2,1),D10<>""),E10,"") -> 30000 | J10: =IF(I10="","",RANK(I10,$I$2:$I$1014,0)+COUNTIF($I$2:I10,I10)-1) -> #REF!
A11: 46227 | B11: Đồ uống | C11: Bản thân | D11: Nước cam | E11: 10000 | F11: Momo | G11: Bà Dung | H11: Bản thân | I11: =IF(AND(A11>=Dashboard!$B$2,A11<EDATE(Dashboard!$B$2,1),D11<>""),E11,"") -> 10000 | J11: =IF(I11="","",RANK(I11,$I$2:$I$1014,0)+COUNTIF($I$2:I11,I11)-1) -> #REF!
A12: 46227 | B12: Di chuyển | C12: Bản thân | D12: Về quê | E12: 145000 | F12: Thẻ SHB | G12: Đồng Phước | H12: Bản thân | I12: =IF(AND(A12>=Dashboard!$B$2,A12<EDATE(Dashboard!$B$2,1),D12<>""),E12,"") -> 145000 | J12: =IF(I12="","",RANK(I12,$I$2:$I$1014,0)+COUNTIF($I$2:I12,I12)-1) -> #REF!
A13: 46227 | B13: Khác | C13: Bản thân | D13: Đám tang | E13: 200000 | F13: Momo | G13: Ngoại thằng Hậu | H13: Khác | I13: =IF(AND(A13>=Dashboard!$B$2,A13<EDATE(Dashboard!$B$2,1),D13<>""),E13,"") -> 200000 | J13: =IF(I13="","",RANK(I13,$I$2:$I$1014,0)+COUNTIF($I$2:I13,I13)-1) -> #REF!
A14: 46227 | B14: Ăn tối | C14: Bản thân | D14: Hủ tíu bò kho | E14: 30000 | F14: Momo | G14: Hồ Bá Kiện | H14: Bản thân | I14: =IF(AND(A14>=Dashboard!$B$2,A14<EDATE(Dashboard!$B$2,1),D14<>""),E14,"") -> 30000 | J14: =IF(I14="","",RANK(I14,$I$2:$I$1014,0)+COUNTIF($I$2:I14,I14)-1) -> #REF!
A15: 46227 | B15: Đồ uống | C15: Bản thân | D15: Nước mía | E15: 12000 | F15: Momo | G15: Hồ Bá Kiện | H15: Bản thân | I15: =IF(AND(A15>=Dashboard!$B$2,A15<EDATE(Dashboard!$B$2,1),D15<>""),E15,"") -> 12000 | J15: =IF(I15="","",RANK(I15,$I$2:$I$1014,0)+COUNTIF($I$2:I15,I15)-1) -> #REF!
A16: 46228 | B16: May mắn | C16: Bản thân | D16: Vé số | E16: 50000 | F16: Tiền mặt | H16: Bản thân | I16: =IF(AND(A16>=Dashboard!$B$2,A16<EDATE(Dashboard!$B$2,1),D16<>""),E16,"") -> 50000 | J16: =IF(I16="","",RANK(I16,$I$2:$I$1014,0)+COUNTIF($I$2:I16,I16)-1) -> #REF!
A17: 46228 | B17: Ăn sáng | C17: Bản thân | D17: Hủ tiếu | E17: 20000 | F17: Tiền mặt | G17: Cô 7 | H17: Bản thân | I17: =IF(AND(A17>=Dashboard!$B$2,A17<EDATE(Dashboard!$B$2,1),D17<>""),E17,"") -> 20000 | J17: =IF(I17="","",RANK(I17,$I$2:$I$1014,0)+COUNTIF($I$2:I17,I17)-1) -> #REF!
A18: 46228 | B18: Ăn sáng | C18: Vú | D18: Hủ tiếu | E18: 10000 | F18: Tiền mặt | G18: Bà Trang | H18: Vú | I18: =IF(AND(A18>=Dashboard!$B$2,A18<EDATE(Dashboard!$B$2,1),D18<>""),E18,"") -> 10000 | J18: =IF(I18="","",RANK(I18,$I$2:$I$1014,0)+COUNTIF($I$2:I18,I18)-1) -> #REF!
A19: 46228 | B19: Ăn sáng | C19: Con | D19: Bánh bao | E19: 38000 | F19: Tiền mặt | G19: Công viên | H19: Con | I19: =IF(AND(A19>=Dashboard!$B$2,A19<EDATE(Dashboard!$B$2,1),D19<>""),E19,"") -> 38000 | J19: =IF(I19="","",RANK(I19,$I$2:$I$1014,0)+COUNTIF($I$2:I19,I19)-1) -> #REF!
A20: 46228 | B20: Đồ uống | C20: Con | D20: Reveive lạnh | E20: 20000 | F20: Tiền mặt | G20: Trụ nước công cộng | H20: Con | I20: =IF(AND(A20>=Dashboard!$B$2,A20<EDATE(Dashboard!$B$2,1),D20<>""),E20,"") -> 20000 | J20: =IF(I20="","",RANK(I20,$I$2:$I$1014,0)+COUNTIF($I$2:I20,I20)-1) -> #REF!
A21: 46228 | B21: Đồ ăn | C21: Gia đình | D21: Bó sổ | E21: 50000 | F21: Tiền mặt | G21: Cô 7 | I21: =IF(AND(A21>=Dashboard!$B$2,A21<EDATE(Dashboard!$B$2,1),D21<>""),E21,"") -> 50000 | J21: =IF(I21="","",RANK(I21,$I$2:$I$1014,0)+COUNTIF($I$2:I21,I21)-1) -> #REF!
A22: 46228 | B22: Đổ xăng | C22: Mẹ | D22: Di chuyển | E22: 60000 | F22: Thẻ SHB | G22: Xăng | I22: =IF(AND(A22>=Dashboard!$B$2,A22<EDATE(Dashboard!$B$2,1),D22<>""),E22,"") -> 60000 | J22: =IF(I22="","",RANK(I22,$I$2:$I$1014,0)+COUNTIF($I$2:I22,I22)-1) -> #REF!
A23: 46229 | B23: Ăn sáng | C23: Gia đình | D23: Bún bò | E23: 120000 | F23: Tiền mặt | G23: Cmtt Tây Ninh | I23: =IF(AND(A23>=Dashboard!$B$2,A23<EDATE(Dashboard!$B$2,1),D23<>""),E23,"") -> 120000 | J23: =IF(I23="","",RANK(I23,$I$2:$I$1014,0)+COUNTIF($I$2:I23,I23)-1) -> #REF!
A24: 46229 | B24: May mắn | C24: Bản thân | D24: Vé số | E24: 30000 | F24: Tiền mặt | I24: =IF(AND(A24>=Dashboard!$B$2,A24<EDATE(Dashboard!$B$2,1),D24<>""),E24,"") -> 30000 | J24: =IF(I24="","",RANK(I24,$I$2:$I$1014,0)+COUNTIF($I$2:I24,I24)-1) -> #REF!
A25: 46230 | B25: Di chuyển | C25: Bản thân | D25: Đi SG | E25: 145000 | F25: Momo | G25: Đồng Phước | H25: Bản thân | I25: =IF(AND(A25>=Dashboard!$B$2,A25<EDATE(Dashboard!$B$2,1),D25<>""),E25,"") -> 145000 | J25: =IF(I25="","",RANK(I25,$I$2:$I$1014,0)+COUNTIF($I$2:I25,I25)-1) -> #REF!
A26: 46230 | B26: Di chuyển | C26: Bản thân | D26: Grab | E26: 18000 | F26: Thẻ SHB | G26: Từ 43 Cộng Hòa | H26: Bản thân | I26: =IF(AND(A26>=Dashboard!$B$2,A26<EDATE(Dashboard!$B$2,1),D26<>""),E26,"") -> 18000 | J26: =IF(I26="","",RANK(I26,$I$2:$I$1014,0)+COUNTIF($I$2:I26,I26)-1) -> #REF!
A27: 46230 | B27: Cafe | C27: Bản thân | D27: Cà phê sữa | E27: 29000 | F27: Thẻ SHB | G27: Hightlands | H27: Bản thân | I27: =IF(AND(A27>=Dashboard!$B$2,A27<EDATE(Dashboard!$B$2,1),D27<>""),E27,"") -> 29000 | J27: =IF(I27="","",RANK(I27,$I$2:$I$1014,0)+COUNTIF($I$2:I27,I27)-1) -> #REF!
A28: 46230 | B28: Ăn trưa | C28: Bản thân | D28: Cơm | E28: 27000 | F28: VCB | G28: An Nhiên | I28: =IF(AND(A28>=Dashboard!$B$2,A28<EDATE(Dashboard!$B$2,1),D28<>""),E28,"") -> 27000 | J28: =IF(I28="","",RANK(I28,$I$2:$I$1014,0)+COUNTIF($I$2:I28,I28)-1) -> #REF!
A29: 46230 | B29: Đồ ăn | C29: Bản thân | D29: Chè bắp | E29: 12000 | F29: VCB | G29: An Nhiên | I29: =IF(AND(A29>=Dashboard!$B$2,A29<EDATE(Dashboard!$B$2,1),D29<>""),E29,"") -> 12000 | J29: =IF(I29="","",RANK(I29,$I$2:$I$1014,0)+COUNTIF($I$2:I29,I29)-1) -> #REF!
A30: 46230 | B30: May mắn | C30: Bản thân | D30: Vé số | E30: 40000 | F30: Tiền mặt | I30: =IF(AND(A30>=Dashboard!$B$2,A30<EDATE(Dashboard!$B$2,1),D30<>""),E30,"") -> 40000 | J30: =IF(I30="","",RANK(I30,$I$2:$I$1014,0)+COUNTIF($I$2:I30,I30)-1) -> #REF!
A31: 46231 | B31: May mắn | C31: Bản thân | D31: Vé số | E31: 200000 | F31: Tiền mặt | I31: =IF(AND(A31>=Dashboard!$B$2,A31<EDATE(Dashboard!$B$2,1),D31<>""),E31,"") -> 200000 | J31: =IF(I31="","",RANK(I31,$I$2:$I$1014,0)+COUNTIF($I$2:I31,I31)-1) -> #REF!
A32: 46231 | B32: Ăn trưa | C32: Bản thân | D32: Cơm | E32: 27000 | F32: VCB | I32: =IF(AND(A32>=Dashboard!$B$2,A32<EDATE(Dashboard!$B$2,1),D32<>""),E32,"") -> 27000 | J32: =IF(I32="","",RANK(I32,$I$2:$I$1014,0)+COUNTIF($I$2:I32,I32)-1) -> #REF!
A33: 46231 | B33: Đồ uống | C33: Bản thân | D33: Nước dừa | E33: 20000 | F33: Momo | I33: =IF(AND(A33>=Dashboard!$B$2,A33<EDATE(Dashboard!$B$2,1),D33<>""),E33,"") -> 20000 | J33: =IF(I33="","",RANK(I33,$I$2:$I$1014,0)+COUNTIF($I$2:I33,I33)-1) -> #REF!
A34: 46231 | B34: Đồ uống | C34: Bản thân | D34: Nước mía | E34: 12000 | F34: Momo | I34: =IF(AND(A34>=Dashboard!$B$2,A34<EDATE(Dashboard!$B$2,1),D34<>""),E34,"") -> 12000 | J34: =IF(I34="","",RANK(I34,$I$2:$I$1014,0)+COUNTIF($I$2:I34,I34)-1) -> #REF!
A35: 46232 | B35: Cafe | C35: Bản thân | D35: Cà phê sữa | E35: 29000 | F35: Thẻ Kbank | G35: Hightlands | H35: Bản thân | I35: =IF(AND(A35>=Dashboard!$B$2,A35<EDATE(Dashboard!$B$2,1),D35<>""),E35,"") -> 29000 | J35: =IF(I35="","",RANK(I35,$I$2:$I$1014,0)+COUNTIF($I$2:I35,I35)-1) -> #REF!
A36: 46232 | B36: Ăn trưa | C36: Bản thân | D36: Cơm | E36: 27000 | F36: VCB | G36: An Nhiên | H36: Bản thân | I36: =IF(AND(A36>=Dashboard!$B$2,A36<EDATE(Dashboard!$B$2,1),D36<>""),E36,"") -> 27000 | J36: =IF(I36="","",RANK(I36,$I$2:$I$1014,0)+COUNTIF($I$2:I36,I36)-1) -> #REF!
A37: 46232 | B37: Ăn sáng | C37: Bản thân | D37: Xôi | E37: 26000 | F37: Momo | G37: Bánh mì Khôi | H37: Bản thân | I37: =IF(AND(A37>=Dashboard!$B$2,A37<EDATE(Dashboard!$B$2,1),D37<>""),E37,"") -> 26000 | J37: =IF(I37="","",RANK(I37,$I$2:$I$1014,0)+COUNTIF($I$2:I37,I37)-1) -> #REF!
A38: 46232 | B38: Ăn tối | C38: Bản thân | D38: Cơm | E38: 35000 | F38: Momo | G38: Sư vạn hạnh | H38: Bản thân | I38: =IF(AND(A38>=Dashboard!$B$2,A38<EDATE(Dashboard!$B$2,1),D38<>""),E38,"") -> 35000 | J38: =IF(I38="","",RANK(I38,$I$2:$I$1014,0)+COUNTIF($I$2:I38,I38)-1) -> #REF!
A39: 46232 | B39: Khác | C39: Bản thân | D39: Đám tang | E39: 200000 | F39: Momo | G39: Mẹ vợ thằng Hùng | I39: =IF(AND(A39>=Dashboard!$B$2,A39<EDATE(Dashboard!$B$2,1),D39<>""),E39,"") -> 200000 | J39: =IF(I39="","",RANK(I39,$I$2:$I$1014,0)+COUNTIF($I$2:I39,I39)-1) -> #REF!
A40: 46233 | B40: Ăn sáng | C40: Bản thân | D40: Bún Huế | E40: 20000 | F40: Tiền mặt | G40: Chị Châu | H40: Bản thân | I40: =IF(AND(A40>=Dashboard!$B$2,A40<EDATE(Dashboard!$B$2,1),D40<>""),E40,"") -> 20000 | J40: =IF(I40="","",RANK(I40,$I$2:$I$1014,0)+COUNTIF($I$2:I40,I40)-1) -> #REF!
...

Sheet DanhMuc
A1: Nhóm | B1: Tag | C1: Thanh toán | D1: Khoản chi | E1: Số lần tháng | F1: Xếp hạng
A2: Ăn sáng | B2: Bản thân | C2: Momo | D2: Mì Quảng | E2: =COUNTIFS(ChiTieu!D:D,D2,ChiTieu!A:A,">="&Dashboard!$B$2,ChiTieu!A:A,"<"&EDATE(Dashboard!$B$2,1)) -> 1 | F2: =IF(E2=0,"",RANK(E2,$E$2:$E$100,0)+COUNTIF($E$2:E2,E2)-1) -> 5
A3: Ăn trưa | B3: Gia đình | C3: Thẻ SHB | D3: Cà phê sữa | E3: =COUNTIFS(ChiTieu!D:D,D3,ChiTieu!A:A,">="&Dashboard!$B$2,ChiTieu!A:A,"<"&EDATE(Dashboard!$B$2,1)) -> 8 | F3: =IF(E3=0,"",RANK(E3,$E$2:$E$100,0)+COUNTIF($E$2:E3,E3)-1) -> 3
A4: Ăn tối | B4: Về quê | C4: VCB | D4: Cơm | E4: =COUNTIFS(ChiTieu!D:D,D4,ChiTieu!A:A,">="&Dashboard!$B$2,ChiTieu!A:A,"<"&EDATE(Dashboard!$B$2,1)) -> 27 | F4: =IF(E4=0,"",RANK(E4,$E$2:$E$100,0)+COUNTIF($E$2:E4,E4)-1) -> 1
A5: Ăn vặt | B5: Đi chơi hè | C5: App Vietlot | D5: Vietlott | E5: =COUNTIFS(ChiTieu!D:D,D5,ChiTieu!A:A,">="&Dashboard!$B$2,ChiTieu!A:A,"<"&EDATE(Dashboard!$B$2,1)) -> 2 | F5: =IF(E5=0,"",RANK(E5,$E$2:$E$100,0)+COUNTIF($E$2:E5,E5)-1) -> 4
A6: Cafe | B6: Team | C6: Tiền mặt | D6: Vé số | E6: =COUNTIFS(ChiTieu!D:D,D6,ChiTieu!A:A,">="&Dashboard!$B$2,ChiTieu!A:A,"<"&EDATE(Dashboard!$B$2,1)) -> 20 | F6: =IF(E6=0,"",RANK(E6,$E$2:$E$100,0)+COUNTIF($E$2:E6,E6)-1) -> 2
A7: Đồ uống | B7: Khác | C7: Chuyển khoản | D7: Đi chợ | E7: =COUNTIFS(ChiTieu!D:D,D7,ChiTieu!A:A,">="&Dashboard!$B$2,ChiTieu!A:A,"<"&EDATE(Dashboard!$B$2,1)) -> 0 | F7: =IF(E7=0,"",RANK(E7,$E$2:$E$100,0)+COUNTIF($E$2:E7,E7)-1)
A8: Gia đình | C8: Thẻ | D8: Leo núi | E8: =COUNTIFS(ChiTieu!D:D,D8,ChiTieu!A:A,">="&Dashboard!$B$2,ChiTieu!A:A,"<"&EDATE(Dashboard!$B$2,1)) -> 0 | F8: =IF(E8=0,"",RANK(E8,$E$2:$E$100,0)+COUNTIF($E$2:E8,E8)-1)
A9: Di chuyển | D9: Kem | E9: =COUNTIFS(ChiTieu!D:D,D9,ChiTieu!A:A,">="&Dashboard!$B$2,ChiTieu!A:A,"<"&EDATE(Dashboard!$B$2,1)) -> 1 | F9: =IF(E9=0,"",RANK(E9,$E$2:$E$100,0)+COUNTIF($E$2:E9,E9)-1) -> 6
A10: Mua sắm | D10: Siêu thị Co.opmart | E10: =COUNTIFS(ChiTieu!D:D,D10,ChiTieu!A:A,">="&Dashboard!$B$2,ChiTieu!A:A,"<"&EDATE(Dashboard!$B$2,1)) -> 0 | F10: =IF(E10=0,"",RANK(E10,$E$2:$E$100,0)+COUNTIF($E$2:E10,E10)-1)
A11: Vật tư
A12: Công nghệ
A13: Giải trí
A14: Công việc
A15: Sức khỏe
A16: May mắn
A17: Khác
A18: Đồ ăn
A19: Tiền điện
A20: Tiền nước

Sheet TongNgayThang
A1: TỔNG CHI THEO NGÀY VÀ THÁNG | G1: BỘ LỌC TỔNG CHI
A2: Tháng đang xem | B2: =Dashboard!B2 -> 46225 | G2: Chế độ xem | H2: Tất cả
G3: Chọn ngày | H3: 46226
A4: Ngày | B4: Tổng chi ngày | C4: Cột 1 | D4: Tháng | E4: Tổng chi tháng | G4: Chọn tháng | H4: =Dashboard!B2 -> 46225
A5: =$B$2 -> 46225 | B5: =IF(MONTH(A5)=MONTH($B$2),SUMIFS(ChiTieu!$E:$E,ChiTieu!$A:$A,A5),"") -> 0 | D5: =EOMONTH(MIN(ChiTieu!$A$2:$A$1003),-1)+1 -> 46204 | E5: =IF(D5="","",SUMIFS(ChiTieu!$E:$E,ChiTieu!$A:$A,">="&D5,ChiTieu!$A:$A,"<"&EDATE(D5,1))) -> 2284000
A6: =IF(A5="","",IF(A5+1<EDATE($B$2,1),A5+1,"")) -> 46226 | B6: =IF(A6="","",SUMIFS(ChiTieu!$E:$E,ChiTieu!$A:$A,A6)) -> 116000 | D6: =IF(EDATE(D5,1)<=EOMONTH(MAX(ChiTieu!$A$2:$A$1003),-1)+1,EDATE(D5,1),"") -> 46235 | E6: =IF(D6="","",SUMIFS(ChiTieu!$E:$E,ChiTieu!$A:$A,">="&D6,ChiTieu!$A:$A,"<"&EDATE(D6,1))) -> 4666157 | G6: Phạm vi đang xem | H6: =IF(H2="Ngày",TEXT(H3,"dd/mm/yyyy"),IF(H2="Tháng",TEXT(H4,"mm/yyyy"),IF(H2="Tất cả","Toàn bộ dữ liệu","Chọn: Ngày / Tháng / Tất cả"))) -> Toàn bộ dữ liệu
A7: =IF(A6="","",IF(A6+1<EDATE($B$2,1),A6+1,"")) -> 46227 | B7: =IF(A7="","",SUMIFS(ChiTieu!$E:$E,ChiTieu!$A:$A,A7)) -> 490000 | D7: =IF(D6="","",IF(EDATE(D6,1)<=EOMONTH(MAX(ChiTieu!$A$2:$A$1003),-1)+1,EDATE(D6,1),"")) | E7: =IF(D7="","",SUMIFS(ChiTieu!$E:$E,ChiTieu!$A:$A,">="&D7,ChiTieu!$A:$A,"<"&EDATE(D7,1))) | G7: Tổng chi | H7: =IF(H2="Ngày",SUMIFS(ChiTieu!$E:$E,ChiTieu!$A:$A,H3),IF(H2="Tháng",SUMIFS(ChiTieu!$E:$E,ChiTieu!$A:$A,">="&EOMONTH(H4,-1)+1,ChiTieu!$A:$A,"<"&EOMONTH(H4,0)+1),IF(H2="Tất cả",SUM(ChiTieu!$E:$E),0))) -> 6950157
A8: =IF(A7="","",IF(A7+1<EDATE($B$2,1),A7+1,"")) -> 46228 | B8: =IF(A8="","",SUMIFS(ChiTieu!$E:$E,ChiTieu!$A:$A,A8)) -> 248000 | D8: =IF(D7="","",IF(EDATE(D7,1)<=EOMONTH(MAX(ChiTieu!$A$2:$A$1003),-1)+1,EDATE(D7,1),"")) | E8: =IF(D8="","",SUMIFS(ChiTieu!$E:$E,ChiTieu!$A:$A,">="&D8,ChiTieu!$A:$A,"<"&EDATE(D8,1)))
A9: =IF(A8="","",IF(A8+1<EDATE($B$2,1),A8+1,"")) -> 46229 | B9: =IF(A9="","",SUMIFS(ChiTieu!$E:$E,ChiTieu!$A:$A,A9)) -> 150000 | D9: =IF(D8="","",IF(EDATE(D8,1)<=EOMONTH(MAX(ChiTieu!$A$2:$A$1003),-1)+1,EDATE(D8,1),"")) | E9: =IF(D9="","",SUMIFS(ChiTieu!$E:$E,ChiTieu!$A:$A,">="&D9,ChiTieu!$A:$A,"<"&EDATE(D9,1))) | G9: Cách dùng | H9: Đổi H2 thành: Ngày, Tháng hoặc Tất cả
A10: =IF(A9="","",IF(A9+1<EDATE($B$2,1),A9+1,"")) -> 46230 | B10: =IF(A10="","",SUMIFS(ChiTieu!$E:$E,ChiTieu!$A:$A,A10)) -> 271000 | D10: =IF(D9="","",IF(EDATE(D9,1)<=EOMONTH(MAX(ChiTieu!$A$2:$A$1003),-1)+1,EDATE(D9,1),"")) | E10: =IF(D10="","",SUMIFS(ChiTieu!$E:$E,ChiTieu!$A:$A,">="&D10,ChiTieu!$A:$A,"<"&EDATE(D10,1))) | H10: Ngày: chọn tại H3 | Tháng: chọn tại H4
A11: =IF(A10="","",IF(A10+1<EDATE($B$2,1),A10+1,"")) -> 46231 | B11: =IF(A11="","",SUMIFS(ChiTieu!$E:$E,ChiTieu!$A:$A,A11)) -> 259000 | D11: =IF(D10="","",IF(EDATE(D10,1)<=EOMONTH(MAX(ChiTieu!$A$2:$A$1003),-1)+1,EDATE(D10,1),"")) | E11: =IF(D11="","",SUMIFS(ChiTieu!$E:$E,ChiTieu!$A:$A,">="&D11,ChiTieu!$A:$A,"<"&EDATE(D11,1)))
A12: =IF(A11="","",IF(A11+1<EDATE($B$2,1),A11+1,"")) -> 46232 | B12: =IF(A12="","",SUMIFS(ChiTieu!$E:$E,ChiTieu!$A:$A,A12)) -> 317000 | D12: =IF(D11="","",IF(EDATE(D11,1)<=EOMONTH(MAX(ChiTieu!$A$2:$A$1003),-1)+1,EDATE(D11,1),"")) | E12: =IF(D12="","",SUMIFS(ChiTieu!$E:$E,ChiTieu!$A:$A,">="&D12,ChiTieu!$A:$A,"<"&EDATE(D12,1)))
A13: =IF(A12="","",IF(A12+1<EDATE($B$2,1),A12+1,"")) -> 46233 | B13: =IF(A13="","",SUMIFS(ChiTieu!$E:$E,ChiTieu!$A:$A,A13)) -> 188000 | D13: =IF(D12="","",IF(EDATE(D12,1)<=EOMONTH(MAX(ChiTieu!$A$2:$A$1003),-1)+1,EDATE(D12,1),"")) | E13: =IF(D13="","",SUMIFS(ChiTieu!$E:$E,ChiTieu!$A:$A,">="&D13,ChiTieu!$A:$A,"<"&EDATE(D13,1)))
A14: =IF(A13="","",IF(A13+1<EDATE($B$2,1),A13+1,"")) -> 46234 | B14: =IF(A14="","",SUMIFS(ChiTieu!$E:$E,ChiTieu!$A:$A,A14)) -> 245000 | D14: =IF(D13="","",IF(EDATE(D13,1)<=EOMONTH(MAX(ChiTieu!$A$2:$A$1003),-1)+1,EDATE(D13,1),"")) | E14: =IF(D14="","",SUMIFS(ChiTieu!$E:$E,ChiTieu!$A:$A,">="&D14,ChiTieu!$A:$A,"<"&EDATE(D14,1)))
A15: =IF(A14="","",IF(A14+1<EDATE($B$2,1),A14+1,"")) -> 46235 | B15: =IF(A15="","",SUMIFS(ChiTieu!$E:$E,ChiTieu!$A:$A,A15)) -> 128000 | D15: =IF(D14="","",IF(EDATE(D14,1)<=EOMONTH(MAX(ChiTieu!$A$2:$A$1003),-1)+1,EDATE(D14,1),"")) | E15: =IF(D15="","",SUMIFS(ChiTieu!$E:$E,ChiTieu!$A:$A,">="&D15,ChiTieu!$A:$A,"<"&EDATE(D15,1)))
A16: =IF(A15="","",IF(A15+1<EDATE($B$2,1),A15+1,"")) -> 46236 | B16: =IF(A16="","",SUMIFS(ChiTieu!$E:$E,ChiTieu!$A:$A,A16)) -> 110000 | D16: =IF(D15="","",IF(EDATE(D15,1)<=EOMONTH(MAX(ChiTieu!$A$2:$A$1003),-1)+1,EDATE(D15,1),"")) | E16: =IF(D16="","",SUMIFS(ChiTieu!$E:$E,ChiTieu!$A:$A,">="&D16,ChiTieu!$A:$A,"<"&EDATE(D16,1)))
A17: =IF(A16="","",IF(A16+1<EDATE($B$2,1),A16+1,"")) -> 46237 | B17: =IF(A17="","",SUMIFS(ChiTieu!$E:$E,ChiTieu!$A:$A,A17)) -> 331000 | D17: =IF(D16="","",IF(EDATE(D16,1)<=EOMONTH(MAX(ChiTieu!$A$2:$A$1003),-1)+1,EDATE(D16,1),"")) | E17: =IF(D17="","",SUMIFS(ChiTieu!$E:$E,ChiTieu!$A:$A,">="&D17,ChiTieu!$A:$A,"<"&EDATE(D17,1)))
A18: =IF(A17="","",IF(A17+1<EDATE($B$2,1),A17+1,"")) -> 46238 | B18: =IF(A18="","",SUMIFS(ChiTieu!$E:$E,ChiTieu!$A:$A,A18)) -> 1674157 | D18: =IF(D17="","",IF(EDATE(D17,1)<=EOMONTH(MAX(ChiTieu!$A$2:$A$1003),-1)+1,EDATE(D17,1),"")) | E18: =IF(D18="","",SUMIFS(ChiTieu!$E:$E,ChiTieu!$A:$A,">="&D18,ChiTieu!$A:$A,"<"&EDATE(D18,1)))
A19: =IF(A18="","",IF(A18+1<EDATE($B$2,1),A18+1,"")) -> 46239 | B19: =IF(A19="","",SUMIFS(ChiTieu!$E:$E,ChiTieu!$A:$A,A19)) -> 136000 | D19: =IF(D18="","",IF(EDATE(D18,1)<=EOMONTH(MAX(ChiTieu!$A$2:$A$1003),-1)+1,EDATE(D18,1),"")) | E19: =IF(D19="","",SUMIFS(ChiTieu!$E:$E,ChiTieu!$A:$A,">="&D19,ChiTieu!$A:$A,"<"&EDATE(D19,1)))
A20: =IF(A19="","",IF(A19+1<EDATE($B$2,1),A19+1,"")) -> 46240 | B20: =IF(A20="","",SUMIFS(ChiTieu!$E:$E,ChiTieu!$A:$A,A20)) -> 214000 | D20: =IF(D19="","",IF(EDATE(D19,1)<=EOMONTH(MAX(ChiTieu!$A$2:$A$1003),-1)+1,EDATE(D19,1),"")) | E20: =IF(D20="","",SUMIFS(ChiTieu!$E:$E,ChiTieu!$A:$A,">="&D20,ChiTieu!$A:$A,"<"&EDATE(D20,1)))
A21: =IF(A20="","",IF(A20+1<EDATE($B$2,1),A20+1,"")) -> 46241 | B21: =IF(A21="","",SUMIFS(ChiTieu!$E:$E,ChiTieu!$A:$A,A21)) -> 241000 | D21: =IF(D20="","",IF(EDATE(D20,1)<=EOMONTH(MAX(ChiTieu!$A$2:$A$1003),-1)+1,EDATE(D20,1),"")) | E21: =IF(D21="","",SUMIFS(ChiTieu!$E:$E,ChiTieu!$A:$A,">="&D21,ChiTieu!$A:$A,"<"&EDATE(D21,1)))
A22: =IF(A21="","",IF(A21+1<EDATE($B$2,1),A21+1,"")) -> 46242 | B22: =IF(A22="","",SUMIFS(ChiTieu!$E:$E,ChiTieu!$A:$A,A22)) -> 159000 | D22: =IF(D21="","",IF(EDATE(D21,1)<=EOMONTH(MAX(ChiTieu!$A$2:$A$1003),-1)+1,EDATE(D21,1),"")) | E22: =IF(D22="","",SUMIFS(ChiTieu!$E:$E,ChiTieu!$A:$A,">="&D22,ChiTieu!$A:$A,"<"&EDATE(D22,1)))
... A35: =IF(A34="","",IF(A34+1<EDATE($B$2,1),A34+1,"")) -> 46255 | B35: =IF(A35="","",SUMIFS(ChiTieu!$E:$E,ChiTieu!$A:$A,A35)) -> 0 | D35: =IF(D34="","",IF(EDATE(D34,1)<=EOMONTH(MAX(ChiTieu!$A$2:$A$1003),-1)+1,EDATE(D34,1),"")) | E35: =IF(D35="","",SUMIFS(ChiTieu!$E:$E,ChiTieu!$A:$A,">="&D35,ChiTieu!$A:$A,"<"&EDATE(D35,1)))
D36: =IF(D35="","",IF(EDATE(D35,1)<=EOMONTH(MAX(ChiTieu!$A$2:$A$1003),-1)+1,EDATE(D35,1),"")) | E36: =IF(D36="","",SUMIFS(ChiTieu!$E:$E,ChiTieu!$A:$A,">="&D36,ChiTieu!$A:$A,"<"&EDATE(D36,1)))
D37: =IF(D36="","",IF(EDATE(D36,1)<=EOMONTH(MAX(ChiTieu!$A$2:$A$1003),-1)+1,EDATE(D36,1),"")) | E37: =IF(D37="","",SUMIFS(ChiTieu!$E:$E,ChiTieu!$A:$A,">="&D37,ChiTieu!$A:$A,"<"&EDATE(D37,1)))
D38: =IF(D37="","",IF(EDATE(D37,1)<=EOMONTH(MAX(ChiTieu!$A$2:$A$1003),-1)+1,EDATE(D37,1),"")) | E38: =IF(D38="","",SUMIFS(ChiTieu!$E:$E,ChiTieu!$A:$A,">="&D38,ChiTieu!$A:$A,"<"&EDATE(D38,1)))
D39: =IF(D38="","",IF(EDATE(D38,1)<=EOMONTH(MAX(ChiTieu!$A$2:$A$1003),-1)+1,EDATE(D38,1),"")) | E39: =IF(D39="","",SUMIFS(ChiTieu!$E:$E,ChiTieu!$A:$A,">="&D39,ChiTieu!$A:$A,"<"&EDATE(D39,1)))
D40: =IF(D39="","",IF(EDATE(D39,1)<=EOMONTH(MAX(ChiTieu!$A$2:$A$1003),-1)+1,EDATE(D39,1),"")) | E40: =IF(D40="","",SUMIFS(ChiTieu!$E:$E,ChiTieu!$A:$A,">="&D40,ChiTieu!$A:$A,"<"&EDATE(D40,1)))
D41: =IF(D40="","",IF(EDATE(D40,1)<=EOMONTH(MAX(ChiTieu!$A$2:$A$1003),-1)+1,EDATE(D40,1),"")) | E41: =IF(D41="","",SUMIFS(ChiTieu!$E:$E,ChiTieu!$A:$A,">="&D41,ChiTieu!$A:$A,"<"&EDATE(D41,1)))

Sheet Dashboard
A1: DASHBOARD CHI TIÊU CÁ NHÂN
A2: Tháng phân tích | B2: 46225 | D2: Tổng chi tháng | E2: =SUMIFS(ChiTieu!E:E,ChiTieu!A:A,">="&$B$2,ChiTieu!A:A,"<"&EDATE($B$2,1)) -> 6950157 | G2: Tháng trước | H2: =SUMIFS(ChiTieu!E:E,ChiTieu!A:A,">="&EDATE($B$2,-1),ChiTieu!A:A,"<"&$B$2) -> 0 | J2: Thay đổi | K2: =IF(H2=0,IF(E2=0,0,1),E2/H2-1) -> 1
A4: Số giao dịch | B4: =COUNTIFS(ChiTieu!A:A,">="&$B$2,ChiTieu!A:A,"<"&EDATE($B$2,1)) -> 150 | D4: Chi trung bình | E4: =IFERROR(E2/B4,0) -> 46334.38 | G4: Khoản lớn nhất | H4: =IFERROR(MAXIFS(ChiTieu!E:E,ChiTieu!A:A,">="&$B$2,ChiTieu!A:A,"<"&EDATE($B$2,1)),0) -> 1306195 | J4: Tag nổi bật | K4: {=IFERROR(INDEX($E$22:$E$27,MATCH(MAX($F$22:$F$27),$F$22:$F$27,0)),"—")} -> Bản thân
A6: CHI TIÊU THEO NHÓM | E6: TOP 10 KHOẢN CHI NHIỀU TIỀN NHẤT | I6: TOP 10 XUẤT HIỆN NHIỀU NHẤT
A7: Nhóm | B7: Số tiền | C7: Biểu đồ | E7: Khoản chi | F7: Nhóm | G7: Số tiền | I7: Khoản chi | J7: Số lần
A8: =DanhMuc!A2 -> Ăn sáng | B8: =SUMIFS(ChiTieu!E:E,ChiTieu!B:B,A8,ChiTieu!A:A,">="&$B$2,ChiTieu!A:A,"<"&EDATE($B$2,1)) -> 710000 | C8: =IF(OR(B8=0,MAX($B$8:$B$23)=0),"",REPT("█",MAX(1,ROUND(B8/MAX($B$8:$B$23)*18,0)))) -> ███████████ | E8: {=IFERROR(INDEX(ChiTieu!$D$2:$D$1003,MATCH(ROWS($E$8:E8),ChiTieu!$J$2:$J$1003,0)),"")} | F8: {=IF(E8="","",INDEX(ChiTieu!$B$2:$B$1003,MATCH(ROWS($E$8:E8),ChiTieu!$J$2:$J$1003,0)))} | G8: {=IF(E8="","",INDEX(ChiTieu!$E$2:$E$1003,MATCH(ROWS($E$8:E8),ChiTieu!$J$2:$J$1003,0)))} | I8: {=IFERROR(INDEX(DanhMuc!$D$2:$D$100,MATCH(ROWS($I$8:I8),DanhMuc!$F$2:$F$100,0)),"")} -> Cơm | J8: =IF(I8="","",SUMIF(DanhMuc!$D$2:$D$100,I8,DanhMuc!$E$2:$E$100)) -> 27
A9: =DanhMuc!A3 -> Ăn trưa | B9: =SUMIFS(ChiTieu!E:E,ChiTieu!B:B,A9,ChiTieu!A:A,">="&$B$2,ChiTieu!A:A,"<"&EDATE($B$2,1)) -> 552000 | C9: =IF(OR(B9=0,MAX($B$8:$B$23)=0),"",REPT("█",MAX(1,ROUND(B9/MAX($B$8:$B$23)*18,0)))) -> █████████ | E9: {=IFERROR(INDEX(ChiTieu!$D$2:$D$1003,MATCH(ROWS($E$8:E9),ChiTieu!$J$2:$J$1003,0)),"")} | F9: {=IF(E9="","",INDEX(ChiTieu!$B$2:$B$1003,MATCH(ROWS($E$8:E9),ChiTieu!$J$2:$J$1003,0)))} | G9: {=IF(E9="","",INDEX(ChiTieu!$E$2:$E$1003,MATCH(ROWS($E$8:E9),ChiTieu!$J$2:$J$1003,0)))} | I9: {=IFERROR(INDEX(DanhMuc!$D$2:$D$100,MATCH(ROWS($I$8:I9),DanhMuc!$F$2:$F$100,0)),"")} -> Vé số | J9: =IF(I9="","",SUMIF(DanhMuc!$D$2:$D$100,I9,DanhMuc!$E$2:$E$100)) -> 20
A10: =DanhMuc!A4 -> Ăn tối | B10: =SUMIFS(ChiTieu!E:E,ChiTieu!B:B,A10,ChiTieu!A:A,">="&$B$2,ChiTieu!A:A,"<"&EDATE($B$2,1)) -> 509000 | C10: =IF(OR(B10=0,MAX($B$8:$B$23)=0),"",REPT("█",MAX(1,ROUND(B10/MAX($B$8:$B$23)*18,0)))) -> ████████ | E10: {=IFERROR(INDEX(ChiTieu!$D$2:$D$1003,MATCH(ROWS($E$8:E10),ChiTieu!$J$2:$J$1003,0)),"")} | F10: {=IF(E10="","",INDEX(ChiTieu!$B$2:$B$1003,MATCH(ROWS($E$8:E10),ChiTieu!$J$2:$J$1003,0)))} | G10: {=IF(E10="","",INDEX(ChiTieu!$E$2:$E$1003,MATCH(ROWS($E$8:E10),ChiTieu!$J$2:$J$1003,0)))} | I10: {=IFERROR(INDEX(DanhMuc!$D$2:$D$100,MATCH(ROWS($I$8:I10),DanhMuc!$F$2:$F$100,0)),"")} -> Cà phê sữa | J10: =IF(I10="","",SUMIF(DanhMuc!$D$2:$D$100,I10,DanhMuc!$E$2:$E$100)) -> 8
A11: =DanhMuc!A5 -> Ăn vặt | B11: =SUMIFS(ChiTieu!E:E,ChiTieu!B:B,A11,ChiTieu!A:A,">="&$B$2,ChiTieu!A:A,"<"&EDATE($B$2,1)) -> 0 | C11: =IF(OR(B11=0,MAX($B$8:$B$23)=0),"",REPT("█",MAX(1,ROUND(B11/MAX($B$8:$B$23)*18,0)))) | E11: {=IFERROR(INDEX(ChiTieu!$D$2:$D$1003,MATCH(ROWS($E$8:E11),ChiTieu!$J$2:$J$1003,0)),"")} | F11: {=IF(E11="","",INDEX(ChiTieu!$B$2:$B$1003,MATCH(ROWS($E$8:E11),ChiTieu!$J$2:$J$1003,0)))} | G11: {=IF(E11="","",INDEX(ChiTieu!$E$2:$E$1003,MATCH(ROWS($E$8:E11),ChiTieu!$J$2:$J$1003,0)))} | I11: {=IFERROR(INDEX(DanhMuc!$D$2:$D$100,MATCH(ROWS($I$8:I11),DanhMuc!$F$2:$F$100,0)),"")} -> Vietlott | J11: =IF(I11="","",SUMIF(DanhMuc!$D$2:$D$100,I11,DanhMuc!$E$2:$E$100)) -> 2
A12: =DanhMuc!A6 -> Cafe | B12: =SUMIFS(ChiTieu!E:E,ChiTieu!B:B,A12,ChiTieu!A:A,">="&$B$2,ChiTieu!A:A,"<"&EDATE($B$2,1)) -> 481000 | C12: =IF(OR(B12=0,MAX($B$8:$B$23)=0),"",REPT("█",MAX(1,ROUND(B12/MAX($B$8:$B$23)*18,0)))) -> ████████ | E12: {=IFERROR(INDEX(ChiTieu!$D$2:$D$1003,MATCH(ROWS($E$8:E12),ChiTieu!$J$2:$J$1003,0)),"")} | F12: {=IF(E12="","",INDEX(ChiTieu!$B$2:$B$1003,MATCH(ROWS($E$8:E12),ChiTieu!$J$2:$J$1003,0)))} | G12: {=IF(E12="","",INDEX(ChiTieu!$E$2:$E$1003,MATCH(ROWS($E$8:E12),ChiTieu!$J$2:$J$1003,0)))} | I12: {=IFERROR(INDEX(DanhMuc!$D$2:$D$100,MATCH(ROWS($I$8:I12),DanhMuc!$F$2:$F$100,0)),"")} -> Mì Quảng | J12: =IF(I12="","",SUMIF(DanhMuc!$D$2:$D$100,I12,DanhMuc!$E$2:$E$100)) -> 1
A13: =DanhMuc!A7 -> Đồ uống | B13: =SUMIFS(ChiTieu!E:E,ChiTieu!B:B,A13,ChiTieu!A:A,">="&$B$2,ChiTieu!A:A,"<"&EDATE($B$2,1)) -> 396000 | C13: =IF(OR(B13=0,MAX($B$8:$B$23)=0),"",REPT("█",MAX(1,ROUND(B13/MAX($B$8:$B$23)*18,0)))) -> ██████ | E13: {=IFERROR(INDEX(ChiTieu!$D$2:$D$1003,MATCH(ROWS($E$8:E13),ChiTieu!$J$2:$J$1003,0)),"")} | F13: {=IF(E13="","",INDEX(ChiTieu!$B$2:$B$1003,MATCH(ROWS($E$8:E13),ChiTieu!$J$2:$J$1003,0)))} | G13: {=IF(E13="","",INDEX(ChiTieu!$E$2:$E$1003,MATCH(ROWS($E$8:E13),ChiTieu!$J$2:$J$1003,0)))} | I13: {=IFERROR(INDEX(DanhMuc!$D$2:$D$100,MATCH(ROWS($I$8:I13),DanhMuc!$F$2:$F$100,0)),"")} -> Kem | J13: =IF(I13="","",SUMIF(DanhMuc!$D$2:$D$100,I13,DanhMuc!$E$2:$E$100)) -> 1
A14: =DanhMuc!A8 -> Gia đình | B14: =SUMIFS(ChiTieu!E:E,ChiTieu!B:B,A14,ChiTieu!A:A,">="&$B$2,ChiTieu!A:A,"<"&EDATE($B$2,1)) -> 0 | C14: =IF(OR(B14=0,MAX($B$8:$B$23)=0),"",REPT("█",MAX(1,ROUND(B14/MAX($B$8:$B$23)*18,0)))) | E14: {=IFERROR(INDEX(ChiTieu!$D$2:$D$1003,MATCH(ROWS($E$8:E14),ChiTieu!$J$2:$J$1003,0)),"")} | F14: {=IF(E14="","",INDEX(ChiTieu!$B$2:$B$1003,MATCH(ROWS($E$8:E14),ChiTieu!$J$2:$J$1003,0)))} | G14: {=IF(E14="","",INDEX(ChiTieu!$E$2:$E$1003,MATCH(ROWS($E$8:E14),ChiTieu!$J$2:$J$1003,0)))} | I14: {=IFERROR(INDEX(DanhMuc!$D$2:$D$100,MATCH(ROWS($I$8:I14),DanhMuc!$F$2:$F$100,0)),"")} | J14: =IF(I14="","",SUMIF(DanhMuc!$D$2:$D$100,I14,DanhMuc!$E$2:$E$100))
A15: =DanhMuc!A9 -> Di chuyển | B15: =SUMIFS(ChiTieu!E:E,ChiTieu!B:B,A15,ChiTieu!A:A,">="&$B$2,ChiTieu!A:A,"<"&EDATE($B$2,1)) -> 1125000 | C15: =IF(OR(B15=0,MAX($B$8:$B$23)=0),"",REPT("█",MAX(1,ROUND(B15/MAX($B$8:$B$23)*18,0)))) -> ██████████████████ | E15: {=IFERROR(INDEX(ChiTieu!$D$2:$D$1003,MATCH(ROWS($E$8:E15),ChiTieu!$J$2:$J$1003,0)),"")} | F15: {=IF(E15="","",INDEX(ChiTieu!$B$2:$B$1003,MATCH(ROWS($E$8:E15),ChiTieu!$J$2:$J$1003,0)))} | G15: {=IF(E15="","",INDEX(ChiTieu!$E$2:$E$1003,MATCH(ROWS($E$8:E15),ChiTieu!$J$2:$J$1003,0)))} | I15: {=IFERROR(INDEX(DanhMuc!$D$2:$D$100,MATCH(ROWS($I$8:I15),DanhMuc!$F$2:$F$100,0)),"")} | J15: =IF(I15="","",SUMIF(DanhMuc!$D$2:$D$100,I15,DanhMuc!$E$2:$E$100))
A16: =DanhMuc!A10 -> Mua sắm | B16: =SUMIFS(ChiTieu!E:E,ChiTieu!B:B,A16,ChiTieu!A:A,">="&$B$2,ChiTieu!A:A,"<"&EDATE($B$2,1)) -> 0 | C16: =IF(OR(B16=0,MAX($B$8:$B$23)=0),"",REPT("█",MAX(1,ROUND(B16/MAX($B$8:$B$23)*18,0)))) | E16: {=IFERROR(INDEX(ChiTieu!$D$2:$D$1003,MATCH(ROWS($E$8:E16),ChiTieu!$J$2:$J$1003,0)),"")} | F16: {=IF(E16="","",INDEX(ChiTieu!$B$2:$B$1003,MATCH(ROWS($E$8:E16),ChiTieu!$J$2:$J$1003,0)))} | G16: {=IF(E16="","",INDEX(ChiTieu!$E$2:$E$1003,MATCH(ROWS($E$8:E16),ChiTieu!$J$2:$J$1003,0)))} | I16: {=IFERROR(INDEX(DanhMuc!$D$2:$D$100,MATCH(ROWS($I$8:I16),DanhMuc!$F$2:$F$100,0)),"")} | J16: =IF(I16="","",SUMIF(DanhMuc!$D$2:$D$100,I16,DanhMuc!$E$2:$E$100))
A17: =DanhMuc!A11 -> Vật tư | B17: =SUMIFS(ChiTieu!E:E,ChiTieu!B:B,A17,ChiTieu!A:A,">="&$B$2,ChiTieu!A:A,"<"&EDATE($B$2,1)) -> 0 | C17: =IF(OR(B17=0,MAX($B$8:$B$23)=0),"",REPT("█",MAX(1,ROUND(B17/MAX($B$8:$B$23)*18,0)))) | E17: {=IFERROR(INDEX(ChiTieu!$D$2:$D$1003,MATCH(ROWS($E$8:E17),ChiTieu!$J$2:$J$1003,0)),"")} | F17: {=IF(E17="","",INDEX(ChiTieu!$B$2:$B$1003,MATCH(ROWS($E$8:E17),ChiTieu!$J$2:$J$1003,0)))} | G17: {=IF(E17="","",INDEX(ChiTieu!$E$2:$E$1003,MATCH(ROWS($E$8:E17),ChiTieu!$J$2:$J$1003,0)))} | I17: {=IFERROR(INDEX(DanhMuc!$D$2:$D$100,MATCH(ROWS($I$8:I17),DanhMuc!$F$2:$F$100,0)),"")} | J17: =IF(I17="","",SUMIF(DanhMuc!$D$2:$D$100,I17,DanhMuc!$E$2:$E$100))
A18: =DanhMuc!A12 -> Công nghệ | B18: =SUMIFS(ChiTieu!E:E,ChiTieu!B:B,A18,ChiTieu!A:A,">="&$B$2,ChiTieu!A:A,"<"&EDATE($B$2,1)) -> 0 | C18: =IF(OR(B18=0,MAX($B$8:$B$23)=0),"",REPT("█",MAX(1,ROUND(B18/MAX($B$8:$B$23)*18,0))))
A19: =DanhMuc!A13 -> Giải trí | B19: =SUMIFS(ChiTieu!E:E,ChiTieu!B:B,A19,ChiTieu!A:A,">="&$B$2,ChiTieu!A:A,"<"&EDATE($B$2,1)) -> 0 | C19: =IF(OR(B19=0,MAX($B$8:$B$23)=0),"",REPT("█",MAX(1,ROUND(B19/MAX($B$8:$B$23)*18,0))))
A20: =DanhMuc!A14 -> Công việc | B20: =SUMIFS(ChiTieu!E:E,ChiTieu!B:B,A20,ChiTieu!A:A,">="&$B$2,ChiTieu!A:A,"<"&EDATE($B$2,1)) -> 0 | C20: =IF(OR(B20=0,MAX($B$8:$B$23)=0),"",REPT("█",MAX(1,ROUND(B20/MAX($B$8:$B$23)*18,0)))) | E20: CHI TIÊU THEO TAG | I20: THEO PHƯƠNG THỨC THANH TOÁN
A21: =DanhMuc!A15 -> Sức khỏe | B21: =SUMIFS(ChiTieu!E:E,ChiTieu!B:B,A21,ChiTieu!A:A,">="&$B$2,ChiTieu!A:A,"<"&EDATE($B$2,1)) -> 0 | C21: =IF(OR(B21=0,MAX($B$8:$B$23)=0),"",REPT("█",MAX(1,ROUND(B21/MAX($B$8:$B$23)*18,0)))) | E21: Tag | F21: Số tiền | I21: Phương thức | J21: Số tiền
A22: =DanhMuc!A16 -> May mắn | B22: =SUMIFS(ChiTieu!E:E,ChiTieu!B:B,A22,ChiTieu!A:A,">="&$B$2,ChiTieu!A:A,"<"&EDATE($B$2,1)) -> 890000 | C22: =IF(OR(B22=0,MAX($B$8:$B$23)=0),"",REPT("█",MAX(1,ROUND(B22/MAX($B$8:$B$23)*18,0)))) -> ██████████████ | E22: =DanhMuc!B2 -> Bản thân | F22: =SUMIFS(ChiTieu!E:E,ChiTieu!H:H,E22,ChiTieu!A:A,">="&$B$2,ChiTieu!A:A,"<"&EDATE($B$2,1)) -> 3031000 | I22: =DanhMuc!C2 -> Momo | J22: =SUMIFS(ChiTieu!E:E,ChiTieu!F:F,I22,ChiTieu!A:A,">="&$B$2,ChiTieu!A:A,"<"&EDATE($B$2,1)) -> 2587962
A23: =DanhMuc!A17 -> Khác | B23: =SUMIFS(ChiTieu!E:E,ChiTieu!B:B,A23,ChiTieu!A:A,">="&$B$2,ChiTieu!A:A,"<"&EDATE($B$2,1)) -> 400000 | C23: =IF(OR(B23=0,MAX($B$8:$B$23)=0),"",REPT("█",MAX(1,ROUND(B23/MAX($B$8:$B$23)*18,0)))) -> ██████ | E23: =DanhMuc!B3 -> Gia đình | F23: =SUMIFS(ChiTieu!E:E,ChiTieu!H:H,E23,ChiTieu!A:A,">="&$B$2,ChiTieu!A:A,"<"&EDATE($B$2,1)) -> 1720157 | I23: =DanhMuc!C3 -> Thẻ SHB | J23: =SUMIFS(ChiTieu!E:E,ChiTieu!F:F,I23,ChiTieu!A:A,">="&$B$2,ChiTieu!A:A,"<"&EDATE($B$2,1)) -> 607000
E24: =DanhMuc!B4 -> Về quê | F24: =SUMIFS(ChiTieu!E:E,ChiTieu!H:H,E24,ChiTieu!A:A,">="&$B$2,ChiTieu!A:A,"<"&EDATE($B$2,1)) -> 0 | I24: =DanhMuc!C4 -> VCB | J24: =SUMIFS(ChiTieu!E:E,ChiTieu!F:F,I24,ChiTieu!A:A,">="&$B$2,ChiTieu!A:A,"<"&EDATE($B$2,1)) -> 417000
E25: =DanhMuc!B5 -> Đi chơi hè | F25: =SUMIFS(ChiTieu!E:E,ChiTieu!H:H,E25,ChiTieu!A:A,">="&$B$2,ChiTieu!A:A,"<"&EDATE($B$2,1)) -> 0 | I25: =DanhMuc!C5 -> App Vietlot | J25: =SUMIFS(ChiTieu!E:E,ChiTieu!F:F,I25,ChiTieu!A:A,">="&$B$2,ChiTieu!A:A,"<"&EDATE($B$2,1)) -> 100000
A26: Gợi ý: cập nhật cột Tag trong sheet ChiTieu để theo dõi Về quê, Đi chơi hè, Team, Gia đình... | E26: =DanhMuc!B6 -> Team | F26: =SUMIFS(ChiTieu!E:E,ChiTieu!H:H,E26,ChiTieu!A:A,">="&$B$2,ChiTieu!A:A,"<"&EDATE($B$2,1)) -> 0 | I26: =DanhMuc!C6 -> Tiền mặt | J26: =SUMIFS(ChiTieu!E:E,ChiTieu!F:F,I26,ChiTieu!A:A,">="&$B$2,ChiTieu!A:A,"<"&EDATE($B$2,1)) -> 1189000
A27: Danh sách tháng tự động nằm tại sheet DanhMuc, cột B. | E27: =DanhMuc!B7 -> Khác | F27: =SUMIFS(ChiTieu!E:E,ChiTieu!H:H,E27,ChiTieu!A:A,">="&$B$2,ChiTieu!A:A,"<"&EDATE($B$2,1)) -> 200000 | I27: =DanhMuc!C7 -> Chuyển khoản | J27: =SUMIFS(ChiTieu!E:E,ChiTieu!F:F,I27,ChiTieu!A:A,">="&$B$2,ChiTieu!A:A,"<"&EDATE($B$2,1)) -> 0
A28: Lưu ý: dữ liệu tháng 07/2026 có giao dịch ngày 26/07/2026, sau ngày hiện tại 23/07/2026; dashboard vẫn tính các dòng này. | I28: =DanhMuc!C8 -> Thẻ | J28: =SUMIFS(ChiTieu!E:E,ChiTieu!F:F,I28,ChiTieu!A:A,">="&$B$2,ChiTieu!A:A,"<"&EDATE($B$2,1)) -> 0
